2021-11-09 18:09:33,148 - instabot version: 0.117.0 (bot) - INFO - Instabot version: 0.117.0 Started
2021-11-09 18:09:33,148 - instabot version: 0.117.0 (bot) - DEBUG - Bot imported from /Library/Frameworks/Python.framework/Versions/3.9/lib/python3.9/site-packages/instabot/bot/bot.py
2021-11-09 18:09:33,149 - instabot version: 0.117.0 (api_login) - INFO - Not yet logged in starting: PRE-LOGIN FLOW!
2021-11-09 18:09:33,166 - instabot version: 0.117.0 (api) - WARNING - HTTPSConnectionPool(host='i.instagram.com', port=443): Max retries exceeded with url: /api/v1/accounts/get_prefill_candidates/ (Caused by NewConnectionError('<urllib3.connection.HTTPSConnection object at 0x7ff03f2a8640>: Failed to establish a new connection: [Errno 8] nodename nor servname provided, or not known'))
2021-11-09 18:09:33,201 - instabot version: 0.117.0 (api) - WARNING - HTTPSConnectionPool(host='i.instagram.com', port=443): Max retries exceeded with url: /api/v1/qe/sync/ (Caused by NewConnectionError('<urllib3.connection.HTTPSConnection object at 0x7ff03f2a8670>: Failed to establish a new connection: [Errno 8] nodename nor servname provided, or not known'))
2021-11-09 18:09:33,205 - instabot version: 0.117.0 (api) - WARNING - HTTPSConnectionPool(host='i.instagram.com', port=443): Max retries exceeded with url: /api/v1/launcher/sync/ (Caused by NewConnectionError('<urllib3.connection.HTTPSConnection object at 0x7ff03f2a8580>: Failed to establish a new connection: [Errno 8] nodename nor servname provided, or not known'))
2021-11-09 18:09:33,209 - instabot version: 0.117.0 (api) - WARNING - HTTPSConnectionPool(host='i.instagram.com', port=443): Max retries exceeded with url: /api/v1/accounts/contact_point_prefill/ (Caused by NewConnectionError('<urllib3.connection.HTTPSConnection object at 0x7ff03f2a8610>: Failed to establish a new connection: [Errno 8] nodename nor servname provided, or not known'))
